<?xml version="1.0" encoding="UTF-8"?>
<testng-results ignored="0" total="6" passed="3" failed="3" skipped="0">
  <reporter-output>
  </reporter-output>
  <suite started-at="2018-12-26T10:12:55Z" name="Default suite" finished-at="2018-12-26T10:14:07Z" duration-ms="71445">
    <groups>
    </groups>
    <test started-at="2018-12-26T10:12:55Z" name="Default test" finished-at="2018-12-26T10:14:07Z" duration-ms="71445">
      <class name="dataDrivenTest.dataDrivenAddPosition">
        <test-method is-config="true" signature="startBrowser()[pri:0, instance:dataDrivenTest.dataDrivenAddPosition@5aebe890]" started-at="2018-12-26T10:12:55Z" name="startBrowser" finished-at="2018-12-26T10:12:56Z" duration-ms="1140" status="PASS">
          <reporter-output>
          </reporter-output>
        </test-method> <!-- startBrowser -->
        <test-method signature="startApp()[pri:1, instance:dataDrivenTest.dataDrivenAddPosition@5aebe890]" started-at="2018-12-26T10:12:56Z" name="startApp" description="This is the navigating to the url" finished-at="2018-12-26T10:13:03Z" duration-ms="6155" status="PASS">
          <reporter-output>
          </reporter-output>
        </test-method> <!-- startApp -->
        <test-method signature="loginApp(java.lang.String, java.lang.String)[pri:2, instance:dataDrivenTest.dataDrivenAddPosition@5aebe890]" started-at="2018-12-26T10:13:08Z" name="loginApp" description="This is the test case for login" data-provider="loginCredentials" finished-at="2018-12-26T10:13:24Z" duration-ms="15593" status="FAIL">
          <params>
            <param index="0">
              <value>
                <![CDATA[admin@test.com]]>
              </value>
            </param>
            <param index="1">
              <value>
                <![CDATA[demo12]]>
              </value>
            </param>
          </params>
          <exception class="java.lang.AssertionError">
            <message>
              <![CDATA[null]]>
            </message>
            <full-stacktrace>
              <![CDATA[java.lang.AssertionError: null
at org.testng.Assert.fail(Assert.java:96)
at org.testng.Assert.fail(Assert.java:103)
at dataDrivenTest.dataDrivenAddPosition.loginApp(dataDrivenAddPosition.java:84)
at java.base/jdk.internal.reflect.NativeMethodAccessorImpl.invoke0(Native Method)
at java.base/jdk.internal.reflect.NativeMethodAccessorImpl.invoke(NativeMethodAccessorImpl.java:62)
at java.base/jdk.internal.reflect.DelegatingMethodAccessorImpl.invoke(DelegatingMethodAccessorImpl.java:43)
at java.base/java.lang.reflect.Method.invoke(Method.java:564)
at org.testng.internal.MethodInvocationHelper.invokeMethod(MethodInvocationHelper.java:124)
at org.testng.internal.Invoker.invokeMethod(Invoker.java:580)
at org.testng.internal.Invoker.invokeTestMethod(Invoker.java:716)
at org.testng.internal.Invoker.invokeTestMethods(Invoker.java:988)
at org.testng.internal.TestMethodWorker.invokeTestMethods(TestMethodWorker.java:125)
at org.testng.internal.TestMethodWorker.run(TestMethodWorker.java:109)
at org.testng.TestRunner.privateRun(TestRunner.java:648)
at org.testng.TestRunner.run(TestRunner.java:505)
at org.testng.SuiteRunner.runTest(SuiteRunner.java:455)
at org.testng.SuiteRunner.runSequentially(SuiteRunner.java:450)
at org.testng.SuiteRunner.privateRun(SuiteRunner.java:415)
at org.testng.SuiteRunner.run(SuiteRunner.java:364)
at org.testng.SuiteRunnerWorker.runSuite(SuiteRunnerWorker.java:52)
at org.testng.SuiteRunnerWorker.run(SuiteRunnerWorker.java:84)
at org.testng.TestNG.runSuitesSequentially(TestNG.java:1208)
at org.testng.TestNG.runSuitesLocally(TestNG.java:1137)
at org.testng.TestNG.runSuites(TestNG.java:1049)
at org.testng.TestNG.run(TestNG.java:1017)
at org.testng.remote.AbstractRemoteTestNG.run(AbstractRemoteTestNG.java:114)
at org.testng.remote.RemoteTestNG.initAndRun(RemoteTestNG.java:251)
at org.testng.remote.RemoteTestNG.main(RemoteTestNG.java:77)
]]>
            </full-stacktrace>
          </exception> <!-- java.lang.AssertionError -->
          <reporter-output>
          </reporter-output>
        </test-method> <!-- loginApp -->
        <test-method signature="loginApp(java.lang.String, java.lang.String)[pri:2, instance:dataDrivenTest.dataDrivenAddPosition@5aebe890]" started-at="2018-12-26T10:13:24Z" name="loginApp" description="This is the test case for login" data-provider="loginCredentials" finished-at="2018-12-26T10:13:30Z" duration-ms="6106" status="PASS">
          <params>
            <param index="0">
              <value>
                <![CDATA[recruitertester2@hiupapp.com]]>
              </value>
            </param>
            <param index="1">
              <value>
                <![CDATA[Test12345]]>
              </value>
            </param>
          </params>
          <reporter-output>
          </reporter-output>
        </test-method> <!-- loginApp -->
        <test-method signature="loginApp(java.lang.String, java.lang.String)[pri:2, instance:dataDrivenTest.dataDrivenAddPosition@5aebe890]" started-at="2018-12-26T10:13:30Z" name="loginApp" description="This is the test case for login" data-provider="loginCredentials" finished-at="2018-12-26T10:13:45Z" duration-ms="15435" status="FAIL">
          <params>
            <param index="0">
              <value>
                <![CDATA[hello@hiupapp]]>
              </value>
            </param>
            <param index="1">
              <value>
                <![CDATA[Testnn2]]>
              </value>
            </param>
          </params>
          <exception class="java.lang.AssertionError">
            <message>
              <![CDATA[null]]>
            </message>
            <full-stacktrace>
              <![CDATA[java.lang.AssertionError: null
at org.testng.Assert.fail(Assert.java:96)
at org.testng.Assert.fail(Assert.java:103)
at dataDrivenTest.dataDrivenAddPosition.loginApp(dataDrivenAddPosition.java:84)
at java.base/jdk.internal.reflect.NativeMethodAccessorImpl.invoke0(Native Method)
at java.base/jdk.internal.reflect.NativeMethodAccessorImpl.invoke(NativeMethodAccessorImpl.java:62)
at java.base/jdk.internal.reflect.DelegatingMethodAccessorImpl.invoke(DelegatingMethodAccessorImpl.java:43)
at java.base/java.lang.reflect.Method.invoke(Method.java:564)
at org.testng.internal.MethodInvocationHelper.invokeMethod(MethodInvocationHelper.java:124)
at org.testng.internal.Invoker.invokeMethod(Invoker.java:580)
at org.testng.internal.Invoker.invokeTestMethod(Invoker.java:716)
at org.testng.internal.Invoker.invokeTestMethods(Invoker.java:988)
at org.testng.internal.TestMethodWorker.invokeTestMethods(TestMethodWorker.java:125)
at org.testng.internal.TestMethodWorker.run(TestMethodWorker.java:109)
at org.testng.TestRunner.privateRun(TestRunner.java:648)
at org.testng.TestRunner.run(TestRunner.java:505)
at org.testng.SuiteRunner.runTest(SuiteRunner.java:455)
at org.testng.SuiteRunner.runSequentially(SuiteRunner.java:450)
at org.testng.SuiteRunner.privateRun(SuiteRunner.java:415)
at org.testng.SuiteRunner.run(SuiteRunner.java:364)
at org.testng.SuiteRunnerWorker.runSuite(SuiteRunnerWorker.java:52)
at org.testng.SuiteRunnerWorker.run(SuiteRunnerWorker.java:84)
at org.testng.TestNG.runSuitesSequentially(TestNG.java:1208)
at org.testng.TestNG.runSuitesLocally(TestNG.java:1137)
at org.testng.TestNG.runSuites(TestNG.java:1049)
at org.testng.TestNG.run(TestNG.java:1017)
at org.testng.remote.AbstractRemoteTestNG.run(AbstractRemoteTestNG.java:114)
at org.testng.remote.RemoteTestNG.initAndRun(RemoteTestNG.java:251)
at org.testng.remote.RemoteTestNG.main(RemoteTestNG.java:77)
]]>
            </full-stacktrace>
          </exception> <!-- java.lang.AssertionError -->
          <reporter-output>
          </reporter-output>
        </test-method> <!-- loginApp -->
        <test-method signature="loginApp(java.lang.String, java.lang.String)[pri:2, instance:dataDrivenTest.dataDrivenAddPosition@5aebe890]" started-at="2018-12-26T10:13:45Z" name="loginApp" description="This is the test case for login" data-provider="loginCredentials" finished-at="2018-12-26T10:14:01Z" duration-ms="15438" status="FAIL">
          <params>
            <param index="0">
              <value>
                <![CDATA[a1b2c3@we.com]]>
              </value>
            </param>
            <param index="1">
              <value>
                <![CDATA[000999hijf]]>
              </value>
            </param>
          </params>
          <exception class="java.lang.AssertionError">
            <message>
              <![CDATA[null]]>
            </message>
            <full-stacktrace>
              <![CDATA[java.lang.AssertionError: null
at org.testng.Assert.fail(Assert.java:96)
at org.testng.Assert.fail(Assert.java:103)
at dataDrivenTest.dataDrivenAddPosition.loginApp(dataDrivenAddPosition.java:84)
at java.base/jdk.internal.reflect.NativeMethodAccessorImpl.invoke0(Native Method)
at java.base/jdk.internal.reflect.NativeMethodAccessorImpl.invoke(NativeMethodAccessorImpl.java:62)
at java.base/jdk.internal.reflect.DelegatingMethodAccessorImpl.invoke(DelegatingMethodAccessorImpl.java:43)
at java.base/java.lang.reflect.Method.invoke(Method.java:564)
at org.testng.internal.MethodInvocationHelper.invokeMethod(MethodInvocationHelper.java:124)
at org.testng.internal.Invoker.invokeMethod(Invoker.java:580)
at org.testng.internal.Invoker.invokeTestMethod(Invoker.java:716)
at org.testng.internal.Invoker.invokeTestMethods(Invoker.java:988)
at org.testng.internal.TestMethodWorker.invokeTestMethods(TestMethodWorker.java:125)
at org.testng.internal.TestMethodWorker.run(TestMethodWorker.java:109)
at org.testng.TestRunner.privateRun(TestRunner.java:648)
at org.testng.TestRunner.run(TestRunner.java:505)
at org.testng.SuiteRunner.runTest(SuiteRunner.java:455)
at org.testng.SuiteRunner.runSequentially(SuiteRunner.java:450)
at org.testng.SuiteRunner.privateRun(SuiteRunner.java:415)
at org.testng.SuiteRunner.run(SuiteRunner.java:364)
at org.testng.SuiteRunnerWorker.runSuite(SuiteRunnerWorker.java:52)
at org.testng.SuiteRunnerWorker.run(SuiteRunnerWorker.java:84)
at org.testng.TestNG.runSuitesSequentially(TestNG.java:1208)
at org.testng.TestNG.runSuitesLocally(TestNG.java:1137)
at org.testng.TestNG.runSuites(TestNG.java:1049)
at org.testng.TestNG.run(TestNG.java:1017)
at org.testng.remote.AbstractRemoteTestNG.run(AbstractRemoteTestNG.java:114)
at org.testng.remote.RemoteTestNG.initAndRun(RemoteTestNG.java:251)
at org.testng.remote.RemoteTestNG.main(RemoteTestNG.java:77)
]]>
            </full-stacktrace>
          </exception> <!-- java.lang.AssertionError -->
          <reporter-output>
          </reporter-output>
        </test-method> <!-- loginApp -->
        <test-method signature="loginApp(java.lang.String, java.lang.String)[pri:2, instance:dataDrivenTest.dataDrivenAddPosition@5aebe890]" started-at="2018-12-26T10:14:01Z" name="loginApp" description="This is the test case for login" data-provider="loginCredentials" finished-at="2018-12-26T10:14:07Z" duration-ms="5944" status="PASS">
          <params>
            <param index="0">
              <value>
                <![CDATA[recruitertester1@hiupapp.com]]>
              </value>
            </param>
            <param index="1">
              <value>
                <![CDATA[Test12345]]>
              </value>
            </param>
          </params>
          <reporter-output>
          </reporter-output>
        </test-method> <!-- loginApp -->
        <test-method is-config="true" signature="tearDown()[pri:0, instance:dataDrivenTest.dataDrivenAddPosition@5aebe890]" started-at="2018-12-26T10:14:07Z" name="tearDown" finished-at="2018-12-26T10:14:07Z" duration-ms="69" status="PASS">
          <reporter-output>
          </reporter-output>
        </test-method> <!-- tearDown -->
      </class> <!-- dataDrivenTest.dataDrivenAddPosition -->
    </test> <!-- Default test -->
  </suite> <!-- Default suite -->
</testng-results>
